const catchError = (functionName) => {
    try{
        
    }catch(e){
    
    }
} 
export default catchError
